Workbook

Sheet Premissas
A1: SIMULADOR COMERCIAL ORFEU — PREMISSAS
A3: 1. Crescimento e Aceleração
A4: Crescimento orgânico anual — Varejo | B4: 0.255
A5: Crescimento orgânico anual — B2B | B5: 0.255
A6: Bônus de aceleração — ano de entrada na prioridade | B6: 0.25
A7: Bônus de aceleração — 1 ano após entrada | B7: 0.2
A8: Bônus de aceleração — 2 anos após entrada | B8: 0.1
A9: Crescimento orgânico anual — Online | B9: 0.25
A10: 2. Produtividade Comercial (dimensionamento de time)
A11: Meta de faturamento mensal por vendedor (full ramp) | B11: 300000
A12: Meses de ramp-up até atingir a meta | B12: 6
A13: Capacidade anual — ano da contratação (com ramp-up) | B13: =B11*12-B11*B12/2
A14: Capacidade anual — full run-rate (a partir do 2º ano) | B14: =B11*12
A15: Promotores/Abordadores por R$1M incremental (base — antes da sinergia regional, seção 7) | B15: 0.25
A16: Baristas por Comercial consolidado (cidades foco B2B) | B16: 0.5
A18: 3. Span of Control
A19: Mínimo de subordinados por líder | B19: 6
A20: Máximo de subordinados por líder | B20: 12
A21: Médio (referência p/ cálculo de líderes sugeridos) | B21: 9
A23: 4. Metas da Companhia (referência)
A24: Fechamento 2026 (real — atualizado ago/2026) | B24: 163000000
A25: Ambição 2030 | B25: 400000000 | C25: Ambição 2030 é SOMENTE Brasil. Meta consolidada da companhia = R$ 500M (R$ 400M BR + R$ 100M EUA/exportação — ver 'Metas 2030' no Plano de Ação). Sem divergência entre os arquivos.
A27: 5. Priorização de Mercados — fonte: Mercados foco (jul/2026)
A28: Estado | B28: Segmento | C28: Ano de Entrada na Prioridade | G28: Cidades-chave / Observação
A29: SP | B29: Colheita | C29: — | G29: Interior: Campinas (ativo); Sorocaba, SJC, Ribeirão Preto, Jundiaí (2027)
A30: RJ | B30: Colheita | C30: — | G30: —
A31: SC | B31: Plantio | C31: 2026 | G31: Florianópolis, Balneário Camboriú, Itapema (ativo); Blumenau, Joinville (2028)
A32: DF | B32: Plantio | C32: 2026 | G32: Brasília
A33: PR | B33: Plantio | C33: 2026 | G33: Curitiba
A34: RS | B34: Plantio | C34: 2027 | G34: Porto Alegre + Serra Gaúcha (Hoteleiro)
A35: MG | B35: Plantio | C35: 2027 | G35: Belo Horizonte + Nova Lima
A36: ES | B36: Plantio | C36: 2028 | G36: Vitória
A37: BA | B37: Plantio | C37: 2029 | G37: Salvador + Trancoso (Hoteleiro)
A38: CE | B38: Plantio | C38: 2029 | G38: Fortaleza
A39: PE | B39: Plantio | C39: 2029 | G39: Recife + Muro Alto (Hoteleiro)
A40: MS | B40: Plantio | C40: 2030 | G40: Campo Grande + Pantanal (Hoteleiro)
A41: MT | B41: Plantio | C41: 2030 | G41: Cuiabá
A42: AM | B42: Plantio | C42: 2030 | G42: Manaus
A43: AC | B43: Sem priorização definida | C43: — | G43: —
A44: AL | B44: Sem priorização definida | C44: — | G44: —
...

Sheet Base Histórica 2025
A1: BASE HISTÓRICA 2025 — FONTE: Simulador Orfeu.xlsx (Base_Unitaria)
A3: VAREJO TOTAL (Varejo Direto + Representantes) por Estado
A4: UF | B4: Estado | C4: Fat. Bruto 2025 (R$) | D4: Margem Contrib. 2025 (R$) | E4: MC% | F4: Volume (un)
A5: SP | B5: São Paulo | C5: 21741345 | D5: 6947191.5 | E5: =IF(C5=0,0,D5/C5) | F5: 464121
A6: RJ | B6: Rio de Janeiro | C6: 5918211.7 | D6: 1508324 | E6: =IF(C6=0,0,D6/C6) | F6: 195051
A7: SC | B7: Santa Catarina | C7: 11585092 | D7: 2747793.1 | E7: =IF(C7=0,0,D7/C7) | F7: 335304
A8: DF | B8: Distrito Federal | C8: 869314.1 | D8: 275016.95 | E8: =IF(C8=0,0,D8/C8) | F8: 31939
A9: PR | B9: Paraná | C9: 2261077.4 | D9: 587959.2 | E9: =IF(C9=0,0,D9/C9) | F9: 66083
A10: RS | B10: Rio Grande do Sul | C10: 2591730.3 | D10: 442693.83 | E10: =IF(C10=0,0,D10/C10) | F10: 88288
A11: MG | B11: Minas Gerais | C11: 1450691.3 | D11: 430881.58 | E11: =IF(C11=0,0,D11/C11) | F11: 51018
A12: ES | B12: Espírito Santo | C12: 220220.52 | D12: 50170.084 | E12: =IF(C12=0,0,D12/C12) | F12: 8920
A13: BA | B13: Bahia | C13: 117607.08 | D13: 42422.252 | E13: =IF(C13=0,0,D13/C13) | F13: 3389
A14: CE | B14: Ceará | C14: 159336.2 | D14: 51733.247 | E14: =IF(C14=0,0,D14/C14) | F14: 5254
A15: PE | B15: Pernambuco | C15: 170354.16 | D15: 60386.823 | E15: =IF(C15=0,0,D15/C15) | F15: 5725
A16: MS | B16: Mato Grosso do Sul | C16: 132869.4 | D16: 41242.12 | E16: =IF(C16=0,0,D16/C16) | F16: 4744
... A31: TO | B31: Tocantins | C31: 33134.2 | D31: 13656.687 | E31: =IF(C31=0,0,D31/C31) | F31: 904
B32: TOTAL | C32: =SUM(C5:C31) | D32: =SUM(D5:D31)
A34: B2B por Estado
A35: UF | B35: Estado | C35: Fat. Bruto 2025 (R$) | D35: Margem Contrib. 2025 (R$) | E35: MC% | F35: Volume (un)
A36: SP | B36: São Paulo | C36: 15057942 | D36: 4887273.8 | E36: =IF(C36=0,0,D36/C36) | F36: 302681
A37: RJ | B37: Rio de Janeiro | C37: 4459529.1 | D37: 1346430.9 | E37: =IF(C37=0,0,D37/C37) | F37: 90536
A38: SC | B38: Santa Catarina | C38: 745367.96 | D38: 192714.7 | E38: =IF(C38=0,0,D38/C38) | F38: 10686
A39: DF | B39: Distrito Federal | C39: 593541.77 | D39: 241385.54 | E39: =IF(C39=0,0,D39/C39) | F39: 9922
A40: PR | B40: Paraná | C40: 812982.8 | D40: 203382.69 | E40: =IF(C40=0,0,D40/C40) | F40: 13768
A41: RS | B41: Rio Grande do Sul | C41: 315961.81 | D41: 105064.88 | E41: =IF(C41=0,0,D41/C41) | F41: 5283
A42: MG | B42: Minas Gerais | C42: 1414547.8 | D42: 368850.86 | E42: =IF(C42=0,0,D42/C42) | F42: 54910
A43: ES | B43: Espírito Santo | C43: 2700 | D43: 1071.7895 | E43: =IF(C43=0,0,D43/C43) | F43: 36
A44: BA | B44: Bahia | C44: 277487.2 | D44: 122033.24 | E44: =IF(C44=0,0,D44/C44) | F44: 6033
A45: CE | B45: Ceará | C45: 6693 | D45: 2658.4969 | E45: =IF(C45=0,0,D45/C45) | F45: 66
A46: PE | B46: Pernambuco | C46: 324873.15 | D46: 147392.15 | E46: =IF(C46=0,0,D46/C46) | F46: 5992
A47: MS | B47: Mato Grosso do Sul | C47: 50811.1 | D47: 22040.867 | E47: =IF(C47=0,0,D47/C47) | F47: 4649
... A62: TO | B62: Tocantins | C62: 10609.14 | D62: 4843.0873 | E62: =IF(C62=0,0,D62/C62) | F62: 267
B63: TOTAL | C63: =SUM(C36:C62) | D63: =SUM(D36:D62)
A65: B2B — Top 25 Cidades (2025, referência para cidades-foco)
A66: UF | B66: Cidade | C66: Fat. Bruto 2025 (R$)
A67: SP | B67: Sao Paulo | C67: 7342395
A68: RJ | B68: Rio De Janeiro | C68: 3201930
A69: SP | B69: Jundiai | C69: 955415.82
A70: SE | B70: Sao Paulo | C70: 706103.76
A71: MG | B71: Pocos De Caldas | C71: 635771.19
...

Sheet Projeção Receita
A1: PROJEÇÃO DE RECEITA — ESTADO x CANAL (2025 base → 2030)
A3: UF | B3: Estado | C3: Canal | D3: 2025 (base) | E3: 2026 | F3: 2027 | G3: 2028 | H3: 2029 | I3: 2030
A4: SP | B4: São Paulo | C4: Varejo | D4: ='Base Histórica 2025'!C5 | E4: =D4*Premissas!$B$77 | F4: =E4*(1+Premissas!$B$4+IF(ISNUMBER(Premissas!$C$29),IF(2027=Premissas!$C$29,Premissas!$B$6,IF(2027=Premissas!$C$29+1,Premissas!$B$7,IF(2027=Premissas!$C$29+2,Premissas!$B$8,0))),0)) | G4: =F4*(1+Premissas!$B$4+IF(ISNUMBER(Premissas!$C$29),IF(2028=Premissas!$C$29,Premissas!$B$6,IF(2028=Premissas!$C$29+1,Premissas!$B$7,IF(2028=Premissas!$C$29+2,Premissas!$B$8,0))),0)) | H4: =G4*(1+Premissas!$B$4+IF(ISNUMBER(Premissas!$C$29),IF(2029=Premissas!$C$29,Premissas!$B$6,IF(2029=Premissas!$C$29+1,Premissas!$B$7,IF(2029=Premissas!$C$29+2,Premissas!$B$8,0))),0)) | I4: =H4*(1+Premissas!$B$4+IF(ISNUMBER(Premissas!$C$29),IF(2030=Premissas!$C$29,Premissas!$B$6,IF(2030=Premissas!$C$29+1,Premissas!$B$7,IF(2030=Premissas!$C$29+2,Premissas!$B$8,0))),0))
A5: SP | B5: São Paulo | C5: B2B | D5: ='Base Histórica 2025'!C36 | E5: =D5*Premissas!$B$77 | F5: =E5*(1+Premissas!$B$5+IF(ISNUMBER(Premissas!$C$29),IF(2027=Premissas!$C$29,Premissas!$B$6,IF(2027=Premissas!$C$29+1,Premissas!$B$7,IF(2027=Premissas!$C$29+2,Premissas!$B$8,0))),0)) | G5: =F5*(1+Premissas!$B$5+IF(ISNUMBER(Premissas!$C$29),IF(2028=Premissas!$C$29,Premissas!$B$6,IF(2028=Premissas!$C$29+1,Premissas!$B$7,IF(2028=Premissas!$C$29+2,Premissas!$B$8,0))),0)) | H5: =G5*(1+Premissas!$B$5+IF(ISNUMBER(Premissas!$C$29),IF(2029=Premissas!$C$29,Premissas!$B$6,IF(2029=Premissas!$C$29+1,Premissas!$B$7,IF(2029=Premissas!$C$29+2,Premissas!$B$8,0))),0)) | I5: =H5*(1+Premissas!$B$5+IF(ISNUMBER(Premissas!$C$29),IF(2030=Premissas!$C$29,Premissas!$B$6,IF(2030=Premissas!$C$29+1,Premissas!$B$7,IF(2030=Premissas!$C$29+2,Premissas!$B$8,0))),0))
A6: RJ | B6: Rio de Janeiro | C6: Varejo | D6: ='Base Histórica 2025'!C6 | E6: =D6*Premissas!$B$77 | F6: =E6*(1+Premissas!$B$4+IF(ISNUMBER(Premissas!$C$30),IF(2027=Premissas!$C$30,Premissas!$B$6,IF(2027=Premissas!$C$30+1,Premissas!$B$7,IF(2027=Premissas!$C$30+2,Premissas!$B$8,0))),0)) | G6: =F6*(1+Premissas!$B$4+IF(ISNUMBER(Premissas!$C$30),IF(2028=Premissas!$C$30,Premissas!$B$6,IF(2028=Premissas!$C$30+1,Premissas!$B$7,IF(2028=Premissas!$C$30+2,Premissas!$B$8,0))),0)) | H6: =G6*(1+Premissas!$B$4+IF(ISNUMBER(Premissas!$C$30),IF(2029=Premissas!$C$30,Premissas!$B$6,IF(2029=Premissas!$C$30+1,Premissas!$B$7,IF(2029=Premissas!$C$30+2,Premissas!$B$8,0))),0)) | I6: =H6*(1+Premissas!$B$4+IF(ISNUMBER(Premissas!$C$30),IF(2030=Premissas!$C$30,Premissas!$B$6,IF(2030=Premissas!$C$30+1,Premissas!$B$7,IF(2030=Premissas!$C$30+2,Premissas!$B$8,0))),0))
A7: RJ | B7: Rio de Janeiro | C7: B2B | D7: ='Base Histórica 2025'!C37 | E7: =D7*Premissas!$B$77 | F7: =E7*(1+Premissas!$B$5+IF(ISNUMBER(Premissas!$C$30),IF(2027=Premissas!$C$30,Premissas!$B$6,IF(2027=Premissas!$C$30+1,Premissas!$B$7,IF(2027=Premissas!$C$30+2,Premissas!$B$8,0))),0)) | G7: =F7*(1+Premissas!$B$5+IF(ISNUMBER(Premissas!$C$30),IF(2028=Premissas!$C$30,Premissas!$B$6,IF(2028=Premissas!$C$30+1,Premissas!$B$7,IF(2028=Premissas!$C$30+2,Premissas!$B$8,0))),0)) | H7: =G7*(1+Premissas!$B$5+IF(ISNUMBER(Premissas!$C$30),IF(2029=Premissas!$C$30,Premissas!$B$6,IF(2029=Premissas!$C$30+1,Premissas!$B$7,IF(2029=Premissas!$C$30+2,Premissas!$B$8,0))),0)) | I7: =H7*(1+Premissas!$B$5+IF(ISNUMBER(Premissas!$C$30),IF(2030=Premissas!$C$30,Premissas!$B$6,IF(2030=Premissas!$C$30+1,Premissas!$B$7,IF(2030=Premissas!$C$30+2,Premissas!$B$8,0))),0))
A8: SC | B8: Santa Catarina | C8: Varejo | D8: ='Base Histórica 2025'!C7 | E8: =D8*Premissas!$B$77 | F8: =E8*(1+Premissas!$B$4+IF(ISNUMBER(Premissas!$C$31),IF(2027=Premissas!$C$31,Premissas!$B$6,IF(2027=Premissas!$C$31+1,Premissas!$B$7,IF(2027=Premissas!$C$31+2,Premissas!$B$8,0))),0)) | G8: =F8*(1+Premissas!$B$4+IF(ISNUMBER(Premissas!$C$31),IF(2028=Premissas!$C$31,Premissas!$B$6,IF(2028=Premissas!$C$31+1,Premissas!$B$7,IF(2028=Premissas!$C$31+2,Premissas!$B$8,0))),0)) | H8: =G8*(1+Premissas!$B$4+IF(ISNUMBER(Premissas!$C$31),IF(2029=Premissas!$C$31,Premissas!$B$6,IF(2029=Premissas!$C$31+1,Premissas!$B$7,IF(2029=Premissas!$C$31+2,Premissas!$B$8,0))),0)) | I8: =H8*(1+Premissas!$B$4+IF(ISNUMBER(Premissas!$C$31),IF(2030=Premissas!$C$31,Premissas!$B$6,IF(2030=Premissas!$C$31+1,Premissas!$B$7,IF(2030=Premissas!$C$31+2,Premissas!$B$8,0))),0))
A9: SC | B9: Santa Catarina | C9: B2B | D9: ='Base Histórica 2025'!C38 | E9: =D9*Premissas!$B$77 | F9: =E9*(1+Premissas!$B$5+IF(ISNUMBER(Premissas!$C$31),IF(2027=Premissas!$C$31,Premissas!$B$6,IF(2027=Premissas!$C$31+1,Premissas!$B$7,IF(2027=Premissas!$C$31+2,Premissas!$B$8,0))),0)) | G9: =F9*(1+Premissas!$B$5+IF(ISNUMBER(Premissas!$C$31),IF(2028=Premissas!$C$31,Premissas!$B$6,IF(2028=Premissas!$C$31+1,Premissas!$B$7,IF(2028=Premissas!$C$31+2,Premissas!$B$8,0))),0)) | H9: =G9*(1+Premissas!$B$5+IF(ISNUMBER(Premissas!$C$31),IF(2029=Premissas!$C$31,Premissas!$B$6,IF(2029=Premissas!$C$31+1,Premissas!$B$7,IF(2029=Premissas!$C$31+2,Premissas!$B$8,0))),0)) | I9: =H9*(1+Premissas!$B$5+IF(ISNUMBER(Premissas!$C$31),IF(2030=Premissas!$C$31,Premissas!$B$6,IF(2030=Premissas!$C$31+1,Premissas!$B$7,IF(2030=Premissas!$C$31+2,Premissas!$B$8,0))),0))
A10: DF | B10: Distrito Federal | C10: Varejo | D10: ='Base Histórica 2025'!C8 | E10: =D10*Premissas!$B$77 | F10: =E10*(1+Premissas!$B$4+IF(ISNUMBER(Premissas!$C$32),IF(2027=Premissas!$C$32,Premissas!$B$6,IF(2027=Premissas!$C$32+1,Premissas!$B$7,IF(2027=Premissas!$C$32+2,Premissas!$B$8,0))),0)) | G10: =F10*(1+Premissas!$B$4+IF(ISNUMBER(Premissas!$C$32),IF(2028=Premissas!$C$32,Premissas!$B$6,IF(2028=Premissas!$C$32+1,Premissas!$B$7,IF(2028=Premissas!$C$32+2,Premissas!$B$8,0))),0)) | H10: =G10*(1+Premissas!$B$4+IF(ISNUMBER(Premissas!$C$32),IF(2029=Premissas!$C$32,Premissas!$B$6,IF(2029=Premissas!$C$32+1,Premissas!$B$7,IF(2029=Premissas!$C$32+2,Premissas!$B$8,0))),0)) | I10: =H10*(1+Premissas!$B$4+IF(ISNUMBER(Premissas!$C$32),IF(2030=Premissas!$C$32,Premissas!$B$6,IF(2030=Premissas!$C$32+1,Premissas!$B$7,IF(2030=Premissas!$C$32+2,Premissas!$B$8,0))),0))
A11: DF | B11: Distrito Federal | C11: B2B | D11: ='Base Histórica 2025'!C39 | E11: =D11*Premissas!$B$77 | F11: =E11*(1+Premissas!$B$5+IF(ISNUMBER(Premissas!$C$32),IF(2027=Premissas!$C$32,Premissas!$B$6,IF(2027=Premissas!$C$32+1,Premissas!$B$7,IF(2027=Premissas!$C$32+2,Premissas!$B$8,0))),0)) | G11: =F11*(1+Premissas!$B$5+IF(ISNUMBER(Premissas!$C$32),IF(2028=Premissas!$C$32,Premissas!$B$6,IF(2028=Premissas!$C$32+1,Premissas!$B$7,IF(2028=Premissas!$C$32+2,Premissas!$B$8,0))),0)) | H11: =G11*(1+Premissas!$B$5+IF(ISNUMBER(Premissas!$C$32),IF(2029=Premissas!$C$32,Premissas!$B$6,IF(2029=Premissas!$C$32+1,Premissas!$B$7,IF(2029=Premissas!$C$32+2,Premissas!$B$8,0))),0)) | I11: =H11*(1+Premissas!$B$5+IF(ISNUMBER(Premissas!$C$32),IF(2030=Premissas!$C$32,Premissas!$B$6,IF(2030=Premissas!$C$32+1,Premissas!$B$7,IF(2030=Premissas!$C$32+2,Premissas!$B$8,0))),0))
A12: PR | B12: Paraná | C12: Varejo | D12: ='Base Histórica 2025'!C9 | E12: =D12*Premissas!$B$77 | F12: =E12*(1+Premissas!$B$4+IF(ISNUMBER(Premissas!$C$33),IF(2027=Premissas!$C$33,Premissas!$B$6,IF(2027=Premissas!$C$33+1,Premissas!$B$7,IF(2027=Premissas!$C$33+2,Premissas!$B$8,0))),0)) | G12: =F12*(1+Premissas!$B$4+IF(ISNUMBER(Premissas!$C$33),IF(2028=Premissas!$C$33,Premissas!$B$6,IF(2028=Premissas!$C$33+1,Premissas!$B$7,IF(2028=Premissas!$C$33+2,Premissas!$B$8,0))),0)) | H12: =G12*(1+Premissas!$B$4+IF(ISNUMBER(Premissas!$C$33),IF(2029=Premissas!$C$33,Premissas!$B$6,IF(2029=Premissas!$C$33+1,Premissas!$B$7,IF(2029=Premissas!$C$33+2,Premissas!$B$8,0))),0)) | I12: =H12*(1+Premissas!$B$4+IF(ISNUMBER(Premissas!$C$33),IF(2030=Premissas!$C$33,Premissas!$B$6,IF(2030=Premissas!$C$33+1,Premissas!$B$7,IF(2030=Premissas!$C$33+2,Premissas!$B$8,0))),0))
A13: PR | B13: Paraná | C13: B2B | D13: ='Base Histórica 2025'!C40 | E13: =D13*Premissas!$B$77 | F13: =E13*(1+Premissas!$B$5+IF(ISNUMBER(Premissas!$C$33),IF(2027=Premissas!$C$33,Premissas!$B$6,IF(2027=Premissas!$C$33+1,Premissas!$B$7,IF(2027=Premissas!$C$33+2,Premissas!$B$8,0))),0)) | G13: =F13*(1+Premissas!$B$5+IF(ISNUMBER(Premissas!$C$33),IF(2028=Premissas!$C$33,Premissas!$B$6,IF(2028=Premissas!$C$33+1,Premissas!$B$7,IF(2028=Premissas!$C$33+2,Premissas!$B$8,0))),0)) | H13: =G13*(1+Premissas!$B$5+IF(ISNUMBER(Premissas!$C$33),IF(2029=Premissas!$C$33,Premissas!$B$6,IF(2029=Premissas!$C$33+1,Premissas!$B$7,IF(2029=Premissas!$C$33+2,Premissas!$B$8,0))),0)) | I13: =H13*(1+Premissas!$B$5+IF(ISNUMBER(Premissas!$C$33),IF(2030=Premissas!$C$33,Premissas!$B$6,IF(2030=Premissas!$C$33+1,Premissas!$B$7,IF(2030=Premissas!$C$33+2,Premissas!$B$8,0))),0))
A14: RS | B14: Rio Grande do Sul | C14: Varejo | D14: ='Base Histórica 2025'!C10 | E14: =D14*Premissas!$B$77 | F14: =E14*(1+Premissas!$B$4+IF(ISNUMBER(Premissas!$C$34),IF(2027=Premissas!$C$34,Premissas!$B$6,IF(2027=Premissas!$C$34+1,Premissas!$B$7,IF(2027=Premissas!$C$34+2,Premissas!$B$8,0))),0)) | G14: =F14*(1+Premissas!$B$4+IF(ISNUMBER(Premissas!$C$34),IF(2028=Premissas!$C$34,Premissas!$B$6,IF(2028=Premissas!$C$34+1,Premissas!$B$7,IF(2028=Premissas!$C$34+2,Premissas!$B$8,0))),0)) | H14: =G14*(1+Premissas!$B$4+IF(ISNUMBER(Premissas!$C$34),IF(2029=Premissas!$C$34,Premissas!$B$6,IF(2029=Premissas!$C$34+1,Premissas!$B$7,IF(2029=Premissas!$C$34+2,Premissas!$B$8,0))),0)) | I14: =H14*(1+Premissas!$B$4+IF(ISNUMBER(Premissas!$C$34),IF(2030=Premissas!$C$34,Premissas!$B$6,IF(2030=Premissas!$C$34+1,Premissas!$B$7,IF(2030=Premissas!$C$34+2,Premissas!$B$8,0))),0))
A15: RS | B15: Rio Grande do Sul | C15: B2B | D15: ='Base Histórica 2025'!C41 | E15: =D15*Premissas!$B$77 | F15: =E15*(1+Premissas!$B$5+IF(ISNUMBER(Premissas!$C$34),IF(2027=Premissas!$C$34,Premissas!$B$6,IF(2027=Premissas!$C$34+1,Premissas!$B$7,IF(2027=Premissas!$C$34+2,Premissas!$B$8,0))),0)) | G15: =F15*(1+Premissas!$B$5+IF(ISNUMBER(Premissas!$C$34),IF(2028=Premissas!$C$34,Premissas!$B$6,IF(2028=Premissas!$C$34+1,Premissas!$B$7,IF(2028=Premissas!$C$34+2,Premissas!$B$8,0))),0)) | H15: =G15*(1+Premissas!$B$5+IF(ISNUMBER(Premissas!$C$34),IF(2029=Premissas!$C$34,Premissas!$B$6,IF(2029=Premissas!$C$34+1,Premissas!$B$7,IF(2029=Premissas!$C$34+2,Premissas!$B$8,0))),0)) | I15: =H15*(1+Premissas!$B$5+IF(ISNUMBER(Premissas!$C$34),IF(2030=Premissas!$C$34,Premissas!$B$6,IF(2030=Premissas!$C$34+1,Premissas!$B$7,IF(2030=Premissas!$C$34+2,Premissas!$B$8,0))),0))
A16: MG | B16: Minas Gerais | C16: Varejo | D16: ='Base Histórica 2025'!C11 | E16: =D16*Premissas!$B$77 | F16: =E16*(1+Premissas!$B$4+IF(ISNUMBER(Premissas!$C$35),IF(2027=Premissas!$C$35,Premissas!$B$6,IF(2027=Premissas!$C$35+1,Premissas!$B$7,IF(2027=Premissas!$C$35+2,Premissas!$B$8,0))),0)) | G16: =F16*(1+Premissas!$B$4+IF(ISNUMBER(Premissas!$C$35),IF(2028=Premissas!$C$35,Premissas!$B$6,IF(2028=Premissas!$C$35+1,Premissas!$B$7,IF(2028=Premissas!$C$35+2,Premissas!$B$8,0))),0)) | H16: =G16*(1+Premissas!$B$4+IF(ISNUMBER(Premissas!$C$35),IF(2029=Premissas!$C$35,Premissas!$B$6,IF(2029=Premissas!$C$35+1,Premissas!$B$7,IF(2029=Premissas!$C$35+2,Premissas!$B$8,0))),0)) | I16: =H16*(1+Premissas!$B$4+IF(ISNUMBER(Premissas!$C$35),IF(2030=Premissas!$C$35,Premissas!$B$6,IF(2030=Premissas!$C$35+1,Premissas!$B$7,IF(2030=Premissas!$C$35+2,Premissas!$B$8,0))),0))
A17: MG | B17: Minas Gerais | C17: B2B | D17: ='Base Histórica 2025'!C42 | E17: =D17*Premissas!$B$77 | F17: =E17*(1+Premissas!$B$5+IF(ISNUMBER(Premissas!$C$35),IF(2027=Premissas!$C$35,Premissas!$B$6,IF(2027=Premissas!$C$35+1,Premissas!$B$7,IF(2027=Premissas!$C$35+2,Premissas!$B$8,0))),0)) | G17: =F17*(1+Premissas!$B$5+IF(ISNUMBER(Premissas!$C$35),IF(2028=Premissas!$C$35,Premissas!$B$6,IF(2028=Premissas!$C$35+1,Premissas!$B$7,IF(2028=Premissas!$C$35+2,Premissas!$B$8,0))),0)) | H17: =G17*(1+Premissas!$B$5+IF(ISNUMBER(Premissas!$C$35),IF(2029=Premissas!$C$35,Premissas!$B$6,IF(2029=Premissas!$C$35+1,Premissas!$B$7,IF(2029=Premissas!$C$35+2,Premissas!$B$8,0))),0)) | I17: =H17*(1+Premissas!$B$5+IF(ISNUMBER(Premissas!$C$35),IF(2030=Premissas!$C$35,Premissas!$B$6,IF(2030=Premissas!$C$35+1,Premissas!$B$7,IF(2030=Premissas!$C$35+2,Premissas!$B$8,0))),0))
A18: ES | B18: Espírito Santo | C18: Varejo | D18: ='Base Histórica 2025'!C12 | E18: =D18*Premissas!$B$77 | F18: =E18*(1+Premissas!$B$4+IF(ISNUMBER(Premissas!$C$36),IF(2027=Premissas!$C$36,Premissas!$B$6,IF(2027=Premissas!$C$36+1,Premissas!$B$7,IF(2027=Premissas!$C$36+2,Premissas!$B$8,0))),0)) | G18: =F18*(1+Premissas!$B$4+IF(ISNUMBER(Premissas!$C$36),IF(2028=Premissas!$C$36,Premissas!$B$6,IF(2028=Premissas!$C$36+1,Premissas!$B$7,IF(2028=Premissas!$C$36+2,Premissas!$B$8,0))),0)) | H18: =G18*(1+Premissas!$B$4+IF(ISNUMBER(Premissas!$C$36),IF(2029=Premissas!$C$36,Premissas!$B$6,IF(2029=Premissas!$C$36+1,Premissas!$B$7,IF(2029=Premissas!$C$36+2,Premissas!$B$8,0))),0)) | I18: =H18*(1+Premissas!$B$4+IF(ISNUMBER(Premissas!$C$36),IF(2030=Premissas!$C$36,Premissas!$B$6,IF(2030=Premissas!$C$36+1,Premissas!$B$7,IF(2030=Premissas!$C$36+2,Premissas!$B$8,0))),0))
A19: ES | B19: Espírito Santo | C19: B2B | D19: ='Base Histórica 2025'!C43 | E19: =D19*Premissas!$B$77 | F19: =E19*(1+Premissas!$B$5+IF(ISNUMBER(Premissas!$C$36),IF(2027=Premissas!$C$36,Premissas!$B$6,IF(2027=Premissas!$C$36+1,Premissas!$B$7,IF(2027=Premissas!$C$36+2,Premissas!$B$8,0))),0)) | G19: =F19*(1+Premissas!$B$5+IF(ISNUMBER(Premissas!$C$36),IF(2028=Premissas!$C$36,Premissas!$B$6,IF(2028=Premissas!$C$36+1,Premissas!$B$7,IF(2028=Premissas!$C$36+2,Premissas!$B$8,0))),0)) | H19: =G19*(1+Premissas!$B$5+IF(ISNUMBER(Premissas!$C$36),IF(2029=Premissas!$C$36,Premissas!$B$6,IF(2029=Premissas!$C$36+1,Premissas!$B$7,IF(2029=Premissas!$C$36+2,Premissas!$B$8,0))),0)) | I19: =H19*(1+Premissas!$B$5+IF(ISNUMBER(Premissas!$C$36),IF(2030=Premissas!$C$36,Premissas!$B$6,IF(2030=Premissas!$C$36+1,Premissas!$B$7,IF(2030=Premissas!$C$36+2,Premissas!$B$8,0))),0))
A20: BA | B20: Bahia | C20: Varejo | D20: ='Base Histórica 2025'!C13 | E20: =D20*Premissas!$B$77 | F20: =E20*(1+Premissas!$B$4+IF(ISNUMBER(Premissas!$C$37),IF(2027=Premissas!$C$37,Premissas!$B$6,IF(2027=Premissas!$C$37+1,Premissas!$B$7,IF(2027=Premissas!$C$37+2,Premissas!$B$8,0))),0)) | G20: =F20*(1+Premissas!$B$4+IF(ISNUMBER(Premissas!$C$37),IF(2028=Premissas!$C$37,Premissas!$B$6,IF(2028=Premissas!$C$37+1,Premissas!$B$7,IF(2028=Premissas!$C$37+2,Premissas!$B$8,0))),0)) | H20: =G20*(1+Premissas!$B$4+IF(ISNUMBER(Premissas!$C$37),IF(2029=Premissas!$C$37,Premissas!$B$6,IF(2029=Premissas!$C$37+1,Premissas!$B$7,IF(2029=Premissas!$C$37+2,Premissas!$B$8,0))),0)) | I20: =H20*(1+Premissas!$B$4+IF(ISNUMBER(Premissas!$C$37),IF(2030=Premissas!$C$37,Premissas!$B$6,IF(2030=Premissas!$C$37+1,Premissas!$B$7,IF(2030=Premissas!$C$37+2,Premissas!$B$8,0))),0))
A21: BA | B21: Bahia | C21: B2B | D21: ='Base Histórica 2025'!C44 | E21: =D21*Premissas!$B$77 | F21: =E21*(1+Premissas!$B$5+IF(ISNUMBER(Premissas!$C$37),IF(2027=Premissas!$C$37,Premissas!$B$6,IF(2027=Premissas!$C$37+1,Premissas!$B$7,IF(2027=Premissas!$C$37+2,Premissas!$B$8,0))),0)) | G21: =F21*(1+Premissas!$B$5+IF(ISNUMBER(Premissas!$C$37),IF(2028=Premissas!$C$37,Premissas!$B$6,IF(2028=Premissas!$C$37+1,Premissas!$B$7,IF(2028=Premissas!$C$37+2,Premissas!$B$8,0))),0)) | H21: =G21*(1+Premissas!$B$5+IF(ISNUMBER(Premissas!$C$37),IF(2029=Premissas!$C$37,Premissas!$B$6,IF(2029=Premissas!$C$37+1,Premissas!$B$7,IF(2029=Premissas!$C$37+2,Premissas!$B$8,0))),0)) | I21: =H21*(1+Premissas!$B$5+IF(ISNUMBER(Premissas!$C$37),IF(2030=Premissas!$C$37,Premissas!$B$6,IF(2030=Premissas!$C$37+1,Premissas!$B$7,IF(2030=Premissas!$C$37+2,Premissas!$B$8,0))),0))
A22: CE | B22: Ceará | C22: Varejo | D22: ='Base Histórica 2025'!C14 | E22: =D22*Premissas!$B$77 | F22: =E22*(1+Premissas!$B$4+IF(ISNUMBER(Premissas!$C$38),IF(2027=Premissas!$C$38,Premissas!$B$6,IF(2027=Premissas!$C$38+1,Premissas!$B$7,IF(2027=Premissas!$C$38+2,Premissas!$B$8,0))),0)) | G22: =F22*(1+Premissas!$B$4+IF(ISNUMBER(Premissas!$C$38),IF(2028=Premissas!$C$38,Premissas!$B$6,IF(2028=Premissas!$C$38+1,Premissas!$B$7,IF(2028=Premissas!$C$38+2,Premissas!$B$8,0))),0)) | H22: =G22*(1+Premissas!$B$4+IF(ISNUMBER(Premissas!$C$38),IF(2029=Premissas!$C$38,Premissas!$B$6,IF(2029=Premissas!$C$38+1,Premissas!$B$7,IF(2029=Premissas!$C$38+2,Premissas!$B$8,0))),0)) | I22: =H22*(1+Premissas!$B$4+IF(ISNUMBER(Premissas!$C$38),IF(2030=Premissas!$C$38,Premissas!$B$6,IF(2030=Premissas!$C$38+1,Premissas!$B$7,IF(2030=Premissas!$C$38+2,Premissas!$B$8,0))),0))
A23: CE | B23: Ceará | C23: B2B | D23: ='Base Histórica 2025'!C45 | E23: =D23*Premissas!$B$77 | F23: =E23*(1+Premissas!$B$5+IF(ISNUMBER(Premissas!$C$38),IF(2027=Premissas!$C$38,Premissas!$B$6,IF(2027=Premissas!$C$38+1,Premissas!$B$7,IF(2027=Premissas!$C$38+2,Premissas!$B$8,0))),0)) | G23: =F23*(1+Premissas!$B$5+IF(ISNUMBER(Premissas!$C$38),IF(2028=Premissas!$C$38,Premissas!$B$6,IF(2028=Premissas!$C$38+1,Premissas!$B$7,IF(2028=Premissas!$C$38+2,Premissas!$B$8,0))),0)) | H23: =G23*(1+Premissas!$B$5+IF(ISNUMBER(Premissas!$C$38),IF(2029=Premissas!$C$38,Premissas!$B$6,IF(2029=Premissas!$C$38+1,Premissas!$B$7,IF(2029=Premissas!$C$38+2,Premissas!$B$8,0))),0)) | I23: =H23*(1+Premissas!$B$5+IF(ISNUMBER(Premissas!$C$38),IF(2030=Premissas!$C$38,Premissas!$B$6,IF(2030=Premissas!$C$38+1,Premissas!$B$7,IF(2030=Premissas!$C$38+2,Premissas!$B$8,0))),0))
A24: PE | B24: Pernambuco | C24: Varejo | D24: ='Base Histórica 2025'!C15 | E24: =D24*Premissas!$B$77 | F24: =E24*(1+Premissas!$B$4+IF(ISNUMBER(Premissas!$C$39),IF(2027=Premissas!$C$39,Premissas!$B$6,IF(2027=Premissas!$C$39+1,Premissas!$B$7,IF(2027=Premissas!$C$39+2,Premissas!$B$8,0))),0)) | G24: =F24*(1+Premissas!$B$4+IF(ISNUMBER(Premissas!$C$39),IF(2028=Premissas!$C$39,Premissas!$B$6,IF(2028=Premissas!$C$39+1,Premissas!$B$7,IF(2028=Premissas!$C$39+2,Premissas!$B$8,0))),0)) | H24: =G24*(1+Premissas!$B$4+IF(ISNUMBER(Premissas!$C$39),IF(2029=Premissas!$C$39,Premissas!$B$6,IF(2029=Premissas!$C$39+1,Premissas!$B$7,IF(2029=Premissas!$C$39+2,Premissas!$B$8,0))),0)) | I24: =H24*(1+Premissas!$B$4+IF(ISNUMBER(Premissas!$C$39),IF(2030=Premissas!$C$39,Premissas!$B$6,IF(2030=Premissas!$C$39+1,Premissas!$B$7,IF(2030=Premissas!$C$39+2,Premissas!$B$8,0))),0))
A25: PE | B25: Pernambuco | C25: B2B | D25: ='Base Histórica 2025'!C46 | E25: =D25*Premissas!$B$77 | F25: =E25*(1+Premissas!$B$5+IF(ISNUMBER(Premissas!$C$39),IF(2027=Premissas!$C$39,Premissas!$B$6,IF(2027=Premissas!$C$39+1,Premissas!$B$7,IF(2027=Premissas!$C$39+2,Premissas!$B$8,0))),0)) | G25: =F25*(1+Premissas!$B$5+IF(ISNUMBER(Premissas!$C$39),IF(2028=Premissas!$C$39,Premissas!$B$6,IF(2028=Premissas!$C$39+1,Premissas!$B$7,IF(2028=Premissas!$C$39+2,Premissas!$B$8,0))),0)) | H25: =G25*(1+Premissas!$B$5+IF(ISNUMBER(Premissas!$C$39),IF(2029=Premissas!$C$39,Premissas!$B$6,IF(2029=Premissas!$C$39+1,Premissas!$B$7,IF(2029=Premissas!$C$39+2,Premissas!$B$8,0))),0)) | I25: =H25*(1+Premissas!$B$5+IF(ISNUMBER(Premissas!$C$39),IF(2030=Premissas!$C$39,Premissas!$B$6,IF(2030=Premissas!$C$39+1,Premissas!$B$7,IF(2030=Premissas!$C$39+2,Premissas!$B$8,0))),0))
A26: MS | B26: Mato Grosso do Sul | C26: Varejo | D26: ='Base Histórica 2025'!C16 | E26: =D26*Premissas!$B$77 | F26: =E26*(1+Premissas!$B$4+IF(ISNUMBER(Premissas!$C$40),IF(2027=Premissas!$C$40,Premissas!$B$6,IF(2027=Premissas!$C$40+1,Premissas!$B$7,IF(2027=Premissas!$C$40+2,Premissas!$B$8,0))),0)) | G26: =F26*(1+Premissas!$B$4+IF(ISNUMBER(Premissas!$C$40),IF(2028=Premissas!$C$40,Premissas!$B$6,IF(2028=Premissas!$C$40+1,Premissas!$B$7,IF(2028=Premissas!$C$40+2,Premissas!$B$8,0))),0)) | H26: =G26*(1+Premissas!$B$4+IF(ISNUMBER(Premissas!$C$40),IF(2029=Premissas!$C$40,Premissas!$B$6,IF(2029=Premissas!$C$40+1,Premissas!$B$7,IF(2029=Premissas!$C$40+2,Premissas!$B$8,0))),0)) | I26: =H26*(1+Premissas!$B$4+IF(ISNUMBER(Premissas!$C$40),IF(2030=Premissas!$C$40,Premissas!$B$6,IF(2030=Premissas!$C$40+1,Premissas!$B$7,IF(2030=Premissas!$C$40+2,Premissas!$B$8,0))),0))
A27: MS | B27: Mato Grosso do Sul | C27: B2B | D27: ='Base Histórica 2025'!C47 | E27: =D27*Premissas!$B$77 | F27: =E27*(1+Premissas!$B$5+IF(ISNUMBER(Premissas!$C$40),IF(2027=Premissas!$C$40,Premissas!$B$6,IF(2027=Premissas!$C$40+1,Premissas!$B$7,IF(2027=Premissas!$C$40+2,Premissas!$B$8,0))),0)) | G27: =F27*(1+Premissas!$B$5+IF(ISNUMBER(Premissas!$C$40),IF(2028=Premissas!$C$40,Premissas!$B$6,IF(2028=Premissas!$C$40+1,Premissas!$B$7,IF(2028=Premissas!$C$40+2,Premissas!$B$8,0))),0)) | H27: =G27*(1+Premissas!$B$5+IF(ISNUMBER(Premissas!$C$40),IF(2029=Premissas!$C$40,Premissas!$B$6,IF(2029=Premissas!$C$40+1,Premissas!$B$7,IF(2029=Premissas!$C$40+2,Premissas!$B$8,0))),0)) | I27: =H27*(1+Premissas!$B$5+IF(ISNUMBER(Premissas!$C$40),IF(2030=Premissas!$C$40,Premissas!$B$6,IF(2030=Premissas!$C$40+1,Premissas!$B$7,IF(2030=Premissas!$C$40+2,Premissas!$B$8,0))),0))
A28: MT | B28: Mato Grosso | C28: Varejo | D28: ='Base Histórica 2025'!C17 | E28: =D28*Premissas!$B$77 | F28: =E28*(1+Premissas!$B$4+IF(ISNUMBER(Premissas!$C$41),IF(2027=Premissas!$C$41,Premissas!$B$6,IF(2027=Premissas!$C$41+1,Premissas!$B$7,IF(2027=Premissas!$C$41+2,Premissas!$B$8,0))),0)) | G28: =F28*(1+Premissas!$B$4+IF(ISNUMBER(Premissas!$C$41),IF(2028=Premissas!$C$41,Premissas!$B$6,IF(2028=Premissas!$C$41+1,Premissas!$B$7,IF(2028=Premissas!$C$41+2,Premissas!$B$8,0))),0)) | H28: =G28*(1+Premissas!$B$4+IF(ISNUMBER(Premissas!$C$41),IF(2029=Premissas!$C$41,Premissas!$B$6,IF(2029=Premissas!$C$41+1,Premissas!$B$7,IF(2029=Premissas!$C$41+2,Premissas!$B$8,0))),0)) | I28: =H28*(1+Premissas!$B$4+IF(ISNUMBER(Premissas!$C$41),IF(2030=Premissas!$C$41,Premissas!$B$6,IF(2030=Premissas!$C$41+1,Premissas!$B$7,IF(2030=Premissas!$C$41+2,Premissas!$B$8,0))),0))
A29: MT | B29: Mato Grosso | C29: B2B | D29: ='Base Histórica 2025'!C48 | E29: =D29*Premissas!$B$77 | F29: =E29*(1+Premissas!$B$5+IF(ISNUMBER(Premissas!$C$41),IF(2027=Premissas!$C$41,Premissas!$B$6,IF(2027=Premissas!$C$41+1,Premissas!$B$7,IF(2027=Premissas!$C$41+2,Premissas!$B$8,0))),0)) | G29: =F29*(1+Premissas!$B$5+IF(ISNUMBER(Premissas!$C$41),IF(2028=Premissas!$C$41,Premissas!$B$6,IF(2028=Premissas!$C$41+1,Premissas!$B$7,IF(2028=Premissas!$C$41+2,Premissas!$B$8,0))),0)) | H29: =G29*(1+Premissas!$B$5+IF(ISNUMBER(Premissas!$C$41),IF(2029=Premissas!$C$41,Premissas!$B$6,IF(2029=Premissas!$C$41+1,Premissas!$B$7,IF(2029=Premissas!$C$41+2,Premissas!$B$8,0))),0)) | I29: =H29*(1+Premissas!$B$5+IF(ISNUMBER(Premissas!$C$41),IF(2030=Premissas!$C$41,Premissas!$B$6,IF(2030=Premissas!$C$41+1,Premissas!$B$7,IF(2030=Premissas!$C$41+2,Premissas!$B$8,0))),0))
A30: AM | B30: Amazonas | C30: Varejo | D30: ='Base Histórica 2025'!C18 | E30: =D30*Premissas!$B$77 | F30: =E30*(1+Premissas!$B$4+IF(ISNUMBER(Premissas!$C$42),IF(2027=Premissas!$C$42,Premissas!$B$6,IF(2027=Premissas!$C$42+1,Premissas!$B$7,IF(2027=Premissas!$C$42+2,Premissas!$B$8,0))),0)) | G30: =F30*(1+Premissas!$B$4+IF(ISNUMBER(Premissas!$C$42),IF(2028=Premissas!$C$42,Premissas!$B$6,IF(2028=Premissas!$C$42+1,Premissas!$B$7,IF(2028=Premissas!$C$42+2,Premissas!$B$8,0))),0)) | H30: =G30*(1+Premissas!$B$4+IF(ISNUMBER(Premissas!$C$42),IF(2029=Premissas!$C$42,Premissas!$B$6,IF(2029=Premissas!$C$42+1,Premissas!$B$7,IF(2029=Premissas!$C$42+2,Premissas!$B$8,0))),0)) | I30: =H30*(1+Premissas!$B$4+IF(ISNUMBER(Premissas!$C$42),IF(2030=Premissas!$C$42,Premissas!$B$6,IF(2030=Premissas!$C$42+1,Premissas!$B$7,IF(2030=Premissas!$C$42+2,Premissas!$B$8,0))),0))
A31: AM | B31: Amazonas | C31: B2B | D31: ='Base Histórica 2025'!C49 | E31: =D31*Premissas!$B$77 | F31: =E31*(1+Premissas!$B$5+IF(ISNUMBER(Premissas!$C$42),IF(2027=Premissas!$C$42,Premissas!$B$6,IF(2027=Premissas!$C$42+1,Premissas!$B$7,IF(2027=Premissas!$C$42+2,Premissas!$B$8,0))),0)) | G31: =F31*(1+Premissas!$B$5+IF(ISNUMBER(Premissas!$C$42),IF(2028=Premissas!$C$42,Premissas!$B$6,IF(2028=Premissas!$C$42+1,Premissas!$B$7,IF(2028=Premissas!$C$42+2,Premissas!$B$8,0))),0)) | H31: =G31*(1+Premissas!$B$5+IF(ISNUMBER(Premissas!$C$42),IF(2029=Premissas!$C$42,Premissas!$B$6,IF(2029=Premissas!$C$42+1,Premissas!$B$7,IF(2029=Premissas!$C$42+2,Premissas!$B$8,0))),0)) | I31: =H31*(1+Premissas!$B$5+IF(ISNUMBER(Premissas!$C$42),IF(2030=Premissas!$C$42,Premissas!$B$6,IF(2030=Premissas!$C$42+1,Premissas!$B$7,IF(2030=Premissas!$C$42+2,Premissas!$B$8,0))),0))
A32: AC | B32: Acre | C32: Varejo | D32: ='Base Histórica 2025'!C19 | E32: =D32*Premissas!$B$77 | F32: =E32*(1+Premissas!$B$4+IF(ISNUMBER(Premissas!$C$43),IF(2027=Premissas!$C$43,Premissas!$B$6,IF(2027=Premissas!$C$43+1,Premissas!$B$7,IF(2027=Premissas!$C$43+2,Premissas!$B$8,0))),0)) | G32: =F32*(1+Premissas!$B$4+IF(ISNUMBER(Premissas!$C$43),IF(2028=Premissas!$C$43,Premissas!$B$6,IF(2028=Premissas!$C$43+1,Premissas!$B$7,IF(2028=Premissas!$C$43+2,Premissas!$B$8,0))),0)) | H32: =G32*(1+Premissas!$B$4+IF(ISNUMBER(Premissas!$C$43),IF(2029=Premissas!$C$43,Premissas!$B$6,IF(2029=Premissas!$C$43+1,Premissas!$B$7,IF(2029=Premissas!$C$43+2,Premissas!$B$8,0))),0)) | I32: =H32*(1+Premissas!$B$4+IF(ISNUMBER(Premissas!$C$43),IF(2030=Premissas!$C$43,Premissas!$B$6,IF(2030=Premissas!$C$43+1,Premissas!$B$7,IF(2030=Premissas!$C$43+2,Premissas!$B$8,0))),0))
A33: AC | B33: Acre | C33: B2B | D33: ='Base Histórica 2025'!C50 | E33: =D33*Premissas!$B$77 | F33: =E33*(1+Premissas!$B$5+IF(ISNUMBER(Premissas!$C$43),IF(2027=Premissas!$C$43,Premissas!$B$6,IF(2027=Premissas!$C$43+1,Premissas!$B$7,IF(2027=Premissas!$C$43+2,Premissas!$B$8,0))),0)) | G33: =F33*(1+Premissas!$B$5+IF(ISNUMBER(Premissas!$C$43),IF(2028=Premissas!$C$43,Premissas!$B$6,IF(2028=Premissas!$C$43+1,Premissas!$B$7,IF(2028=Premissas!$C$43+2,Premissas!$B$8,0))),0)) | H33: =G33*(1+Premissas!$B$5+IF(ISNUMBER(Premissas!$C$43),IF(2029=Premissas!$C$43,Premissas!$B$6,IF(2029=Premissas!$C$43+1,Premissas!$B$7,IF(2029=Premissas!$C$43+2,Premissas!$B$8,0))),0)) | I33: =H33*(1+Premissas!$B$5+IF(ISNUMBER(Premissas!$C$43),IF(2030=Premissas!$C$43,Premissas!$B$6,IF(2030=Premissas!$C$43+1,Premissas!$B$7,IF(2030=Premissas!$C$43+2,Premissas!$B$8,0))),0))
A34: AL | B34: Alagoas | C34: Varejo | D34: ='Base Histórica 2025'!C20 | E34: =D34*Premissas!$B$77 | F34: =E34*(1+Premissas!$B$4+IF(ISNUMBER(Premissas!$C$44),IF(2027=Premissas!$C$44,Premissas!$B$6,IF(2027=Premissas!$C$44+1,Premissas!$B$7,IF(2027=Premissas!$C$44+2,Premissas!$B$8,0))),0)) | G34: =F34*(1+Premissas!$B$4+IF(ISNUMBER(Premissas!$C$44),IF(2028=Premissas!$C$44,Premissas!$B$6,IF(2028=Premissas!$C$44+1,Premissas!$B$7,IF(2028=Premissas!$C$44+2,Premissas!$B$8,0))),0)) | H34: =G34*(1+Premissas!$B$4+IF(ISNUMBER(Premissas!$C$44),IF(2029=Premissas!$C$44,Premissas!$B$6,IF(2029=Premissas!$C$44+1,Premissas!$B$7,IF(2029=Premissas!$C$44+2,Premissas!$B$8,0))),0)) | I34: =H34*(1+Premissas!$B$4+IF(ISNUMBER(Premissas!$C$44),IF(2030=Premissas!$C$44,Premissas!$B$6,IF(2030=Premissas!$C$44+1,Premissas!$B$7,IF(2030=Premissas!$C$44+2,Premissas!$B$8,0))),0))
A35: AL | B35: Alagoas | C35: B2B | D35: ='Base Histórica 2025'!C51 | E35: =D35*Premissas!$B$77 | F35: =E35*(1+Premissas!$B$5+IF(ISNUMBER(Premissas!$C$44),IF(2027=Premissas!$C$44,Premissas!$B$6,IF(2027=Premissas!$C$44+1,Premissas!$B$7,IF(2027=Premissas!$C$44+2,Premissas!$B$8,0))),0)) | G35: =F35*(1+Premissas!$B$5+IF(ISNUMBER(Premissas!$C$44),IF(2028=Premissas!$C$44,Premissas!$B$6,IF(2028=Premissas!$C$44+1,Premissas!$B$7,IF(2028=Premissas!$C$44+2,Premissas!$B$8,0))),0)) | H35: =G35*(1+Premissas!$B$5+IF(ISNUMBER(Premissas!$C$44),IF(2029=Premissas!$C$44,Premissas!$B$6,IF(2029=Premissas!$C$44+1,Premissas!$B$7,IF(2029=Premissas!$C$44+2,Premissas!$B$8,0))),0)) | I35: =H35*(1+Premissas!$B$5+IF(ISNUMBER(Premissas!$C$44),IF(2030=Premissas!$C$44,Premissas!$B$6,IF(2030=Premissas!$C$44+1,Premissas!$B$7,IF(2030=Premissas!$C$44+2,Premissas!$B$8,0))),0))
A36: AP | B36: Amapá | C36: Varejo | D36: ='Base Histórica 2025'!C21 | E36: =D36*Premissas!$B$77 | F36: =E36*(1+Premissas!$B$4+IF(ISNUMBER(Premissas!$C$45),IF(2027=Premissas!$C$45,Premissas!$B$6,IF(2027=Premissas!$C$45+1,Premissas!$B$7,IF(2027=Premissas!$C$45+2,Premissas!$B$8,0))),0)) | G36: =F36*(1+Premissas!$B$4+IF(ISNUMBER(Premissas!$C$45),IF(2028=Premissas!$C$45,Premissas!$B$6,IF(2028=Premissas!$C$45+1,Premissas!$B$7,IF(2028=Premissas!$C$45+2,Premissas!$B$8,0))),0)) | H36: =G36*(1+Premissas!$B$4+IF(ISNUMBER(Premissas!$C$45),IF(2029=Premissas!$C$45,Premissas!$B$6,IF(2029=Premissas!$C$45+1,Premissas!$B$7,IF(2029=Premissas!$C$45+2,Premissas!$B$8,0))),0)) | I36: =H36*(1+Premissas!$B$4+IF(ISNUMBER(Premissas!$C$45),IF(2030=Premissas!$C$45,Premissas!$B$6,IF(2030=Premissas!$C$45+1,Premissas!$B$7,IF(2030=Premissas!$C$45+2,Premissas!$B$8,0))),0))
A37: AP | B37: Amapá | C37: B2B | D37: ='Base Histórica 2025'!C52 | E37: =D37*Premissas!$B$77 | F37: =E37*(1+Premissas!$B$5+IF(ISNUMBER(Premissas!$C$45),IF(2027=Premissas!$C$45,Premissas!$B$6,IF(2027=Premissas!$C$45+1,Premissas!$B$7,IF(2027=Premissas!$C$45+2,Premissas!$B$8,0))),0)) | G37: =F37*(1+Premissas!$B$5+IF(ISNUMBER(Premissas!$C$45),IF(2028=Premissas!$C$45,Premissas!$B$6,IF(2028=Premissas!$C$45+1,Premissas!$B$7,IF(2028=Premissas!$C$45+2,Premissas!$B$8,0))),0)) | H37: =G37*(1+Premissas!$B$5+IF(ISNUMBER(Premissas!$C$45),IF(2029=Premissas!$C$45,Premissas!$B$6,IF(2029=Premissas!$C$45+1,Premissas!$B$7,IF(2029=Premissas!$C$45+2,Premissas!$B$8,0))),0)) | I37: =H37*(1+Premissas!$B$5+IF(ISNUMBER(Premissas!$C$45),IF(2030=Premissas!$C$45,Premissas!$B$6,IF(2030=Premissas!$C$45+1,Premissas!$B$7,IF(2030=Premissas!$C$45+2,Premissas!$B$8,0))),0))
A38: GO | B38: Goiás | C38: Varejo | D38: ='Base Histórica 2025'!C22 | E38: =D38*Premissas!$B$77 | F38: =E38*(1+Premissas!$B$4+IF(ISNUMBER(Premissas!$C$46),IF(2027=Premissas!$C$46,Premissas!$B$6,IF(2027=Premissas!$C$46+1,Premissas!$B$7,IF(2027=Premissas!$C$46+2,Premissas!$B$8,0))),0)) | G38: =F38*(1+Premissas!$B$4+IF(ISNUMBER(Premissas!$C$46),IF(2028=Premissas!$C$46,Premissas!$B$6,IF(2028=Premissas!$C$46+1,Premissas!$B$7,IF(2028=Premissas!$C$46+2,Premissas!$B$8,0))),0)) | H38: =G38*(1+Premissas!$B$4+IF(ISNUMBER(Premissas!$C$46),IF(2029=Premissas!$C$46,Premissas!$B$6,IF(2029=Premissas!$C$46+1,Premissas!$B$7,IF(2029=Premissas!$C$46+2,Premissas!$B$8,0))),0)) | I38: =H38*(1+Premissas!$B$4+IF(ISNUMBER(Premissas!$C$46),IF(2030=Premissas!$C$46,Premissas!$B$6,IF(2030=Premissas!$C$46+1,Premissas!$B$7,IF(2030=Premissas!$C$46+2,Premissas!$B$8,0))),0))
A39: GO | B39: Goiás | C39: B2B | D39: ='Base Histórica 2025'!C53 | E39: =D39*Premissas!$B$77 | F39: =E39*(1+Premissas!$B$5+IF(ISNUMBER(Premissas!$C$46),IF(2027=Premissas!$C$46,Premissas!$B$6,IF(2027=Premissas!$C$46+1,Premissas!$B$7,IF(2027=Premissas!$C$46+2,Premissas!$B$8,0))),0)) | G39: =F39*(1+Premissas!$B$5+IF(ISNUMBER(Premissas!$C$46),IF(2028=Premissas!$C$46,Premissas!$B$6,IF(2028=Premissas!$C$46+1,Premissas!$B$7,IF(2028=Premissas!$C$46+2,Premissas!$B$8,0))),0)) | H39: =G39*(1+Premissas!$B$5+IF(ISNUMBER(Premissas!$C$46),IF(2029=Premissas!$C$46,Premissas!$B$6,IF(2029=Premissas!$C$46+1,Premissas!$B$7,IF(2029=Premissas!$C$46+2,Premissas!$B$8,0))),0)) | I39: =H39*(1+Premissas!$B$5+IF(ISNUMBER(Premissas!$C$46),IF(2030=Premissas!$C$46,Premissas!$B$6,IF(2030=Premissas!$C$46+1,Premissas!$B$7,IF(2030=Premissas!$C$46+2,Premissas!$B$8,0))),0))
A40: MA | B40: Maranhão | C40: Varejo | D40: ='Base Histórica 2025'!C23 | E40: =D40*Premissas!$B$77 | F40: =E40*(1+Premissas!$B$4+IF(ISNUMBER(Premissas!$C$47),IF(2027=Premissas!$C$47,Premissas!$B$6,IF(2027=Premissas!$C$47+1,Premissas!$B$7,IF(2027=Premissas!$C$47+2,Premissas!$B$8,0))),0)) | G40: =F40*(1+Premissas!$B$4+IF(ISNUMBER(Premissas!$C$47),IF(2028=Premissas!$C$47,Premissas!$B$6,IF(2028=Premissas!$C$47+1,Premissas!$B$7,IF(2028=Premissas!$C$47+2,Premissas!$B$8,0))),0)) | H40: =G40*(1+Premissas!$B$4+IF(ISNUMBER(Premissas!$C$47),IF(2029=Premissas!$C$47,Premissas!$B$6,IF(2029=Premissas!$C$47+1,Premissas!$B$7,IF(2029=Premissas!$C$47+2,Premissas!$B$8,0))),0)) | I40: =H40*(1+Premissas!$B$4+IF(ISNUMBER(Premissas!$C$47),IF(2030=Premissas!$C$47,Premissas!$B$6,IF(2030=Premissas!$C$47+1,Premissas!$B$7,IF(2030=Premissas!$C$47+2,Premissas!$B$8,0))),0))
A41: MA | B41: Maranhão | C41: B2B | D41: ='Base Histórica 2025'!C54 | E41: =D41*Premissas!$B$77 | F41: =E41*(1+Premissas!$B$5+IF(ISNUMBER(Premissas!$C$47),IF(2027=Premissas!$C$47,Premissas!$B$6,IF(2027=Premissas!$C$47+1,Premissas!$B$7,IF(2027=Premissas!$C$47+2,Premissas!$B$8,0))),0)) | G41: =F41*(1+Premissas!$B$5+IF(ISNUMBER(Premissas!$C$47),IF(2028=Premissas!$C$47,Premissas!$B$6,IF(2028=Premissas!$C$47+1,Premissas!$B$7,IF(2028=Premissas!$C$47+2,Premissas!$B$8,0))),0)) | H41: =G41*(1+Premissas!$B$5+IF(ISNUMBER(Premissas!$C$47),IF(2029=Premissas!$C$47,Premissas!$B$6,IF(2029=Premissas!$C$47+1,Premissas!$B$7,IF(2029=Premissas!$C$47+2,Premissas!$B$8,0))),0)) | I41: =H41*(1+Premissas!$B$5+IF(ISNUMBER(Premissas!$C$47),IF(2030=Premissas!$C$47,Premissas!$B$6,IF(2030=Premissas!$C$47+1,Premissas!$B$7,IF(2030=Premissas!$C$47+2,Premissas!$B$8,0))),0))
...

Sheet Oportunidade GAP Mix
A1: OPORTUNIDADE DE RECEITA — GAP DE DISTRIBUIÇÃO (MIX)
A2: Simulação de receita incremental a partir do fechamento do GAP de SKUs distribuídos (mix atual x meta), por estado — fonte: mix_oportunidade_redes_prioritarias.xlsx, 18/ago/2026. Análise separada da linha de crescimento orgânico de Varejo já modelada em 'Projeção Receita' — para comparação lado a lado antes de decidir se e como incorporar à linha de Varejo do simulador.
A4: 1. Premissas desta análise
A5: Giro incremental por SKU novo (% do faturamento médio por SKU atual) | E5: 0.5
A6: Anos para fechar o GAP de distribuição (ramp linear a partir de 2026) | E6: 3
A8: Nota de escopo: SKUs atuais e GAP vêm do arquivo de redes prioritárias mapeadas — não cobre necessariamente 100% do faturamento Varejo do estado. Em estados onde essas redes são uma fatia pequena do total, o faturamento médio por SKU abaixo pode estar SUPERESTIMADO. Validar escopo antes de uso operacional.
A10: 2. Cálculo por Estado
A11: Estado | B11: Fat. Bruto Varejo 2025 (R$) | C11: SKUs Atuais (mix) | D11: GAP SKUs (piso 0) | E11: Fat. médio por SKU atual (R$) | F11: Giro incremental / SKU novo (R$) | G11: Receita incremental potencial (R$)
A12: SP | B12: ='Base Histórica 2025'!C5 | C12: 12269 | D12: 4277 | E12: =IF(C12=0,0,B12/C12) | F12: =E12*$E$5 | G12: =D12*F12
A13: RJ | B13: ='Base Histórica 2025'!C6 | C13: 774 | D13: 4281 | E13: =IF(C13=0,0,B13/C13) | F13: =E13*$E$5 | G13: =D13*F13
A14: SC | B14: ='Base Histórica 2025'!C7 | C14: 731 | D14: 2126 | E14: =IF(C14=0,0,B14/C14) | F14: =E14*$E$5 | G14: =D14*F14
A15: PR | B15: ='Base Histórica 2025'!C9 | C15: 1889 | D15: 2930 | E15: =IF(C15=0,0,B15/C15) | F15: =E15*$E$5 | G15: =D15*F15
A16: RS | B16: ='Base Histórica 2025'!C10 | C16: 126 | D16: 450 | E16: =IF(C16=0,0,B16/C16) | F16: =E16*$E$5 | G16: =D16*F16
A17: TOTAL | B17: =SUM(B12:B16) | C17: =SUM(C12:C16) | D17: =SUM(D12:D16) | G17: =SUM(G12:G16)
A19: 3. Ramp Anual — Receita Incremental (fechamento gradual do GAP)
A20: Cada estado fecha seu GAP linearmente ao longo do número de anos definido na premissa acima (início em 2026). Receita incremental do ano = Receita incremental potencial total × MIN(1, (ano-2025)/anos_fechar).
A21: Estado | B21: 2026 | C21: 2027 | D21: 2028 | E21: 2029 | F21: 2030
A22: SP | B22: =$G$12*MIN(1,(2026-2025)/$E$6) | C22: =$G$12*MIN(1,(2027-2025)/$E$6) | D22: =$G$12*MIN(1,(2028-2025)/$E$6) | E22: =$G$12*MIN(1,(2029-2025)/$E$6) | F22: =$G$12*MIN(1,(2030-2025)/$E$6)
A23: RJ | B23: =$G$13*MIN(1,(2026-2025)/$E$6) | C23: =$G$13*MIN(1,(2027-2025)/$E$6) | D23: =$G$13*MIN(1,(2028-2025)/$E$6) | E23: =$G$13*MIN(1,(2029-2025)/$E$6) | F23: =$G$13*MIN(1,(2030-2025)/$E$6)
A24: SC | B24: =$G$14*MIN(1,(2026-2025)/$E$6) | C24: =$G$14*MIN(1,(2027-2025)/$E$6) | D24: =$G$14*MIN(1,(2028-2025)/$E$6) | E24: =$G$14*MIN(1,(2029-2025)/$E$6) | F24: =$G$14*MIN(1,(2030-2025)/$E$6)
A25: PR | B25: =$G$15*MIN(1,(2026-2025)/$E$6) | C25: =$G$15*MIN(1,(2027-2025)/$E$6) | D25: =$G$15*MIN(1,(2028-2025)/$E$6) | E25: =$G$15*MIN(1,(2029-2025)/$E$6) | F25: =$G$15*MIN(1,(2030-2025)/$E$6)
A26: RS | B26: =$G$16*MIN(1,(2026-2025)/$E$6) | C26: =$G$16*MIN(1,(2027-2025)/$E$6) | D26: =$G$16*MIN(1,(2028-2025)/$E$6) | E26: =$G$16*MIN(1,(2029-2025)/$E$6) | F26: =$G$16*MIN(1,(2030-2025)/$E$6)
A27: TOTAL | B27: =SUM(B22:B26) | C27: =SUM(C22:C26) | D27: =SUM(D22:D26) | E27: =SUM(E22:E26) | F27: =SUM(F22:F26)
A29: 4. Comparação — Varejo Orgânico vs. Varejo + Oportunidade GAP Mix
A30: Para inclusão futura na linha de Varejo (se aprovado): soma do crescimento orgânico já modelado em 'Projeção Receita' com a receita incremental do fechamento de GAP (seção 3 acima).
B31: 2026 | C31: 2027 | D31: 2028 | E31: 2029 | F31: 2030
A32: Varejo orgânico (Projeção Receita, SP+RJ+SC+PR+RS) | B32: ='Projeção Receita'!E4+'Projeção Receita'!E6+'Projeção Receita'!E8+'Projeção Receita'!E12+'Projeção Receita'!E14 | C32: ='Projeção Receita'!F4+'Projeção Receita'!F6+'Projeção Receita'!F8+'Projeção Receita'!F12+'Projeção Receita'!F14 | D32: ='Projeção Receita'!G4+'Projeção Receita'!G6+'Projeção Receita'!G8+'Projeção Receita'!G12+'Projeção Receita'!G14 | E32: ='Projeção Receita'!H4+'Projeção Receita'!H6+'Projeção Receita'!H8+'Projeção Receita'!H12+'Projeção Receita'!H14 | F32: ='Projeção Receita'!I4+'Projeção Receita'!I6+'Projeção Receita'!I8+'Projeção Receita'!I12+'Projeção Receita'!I14
A33: + Oportunidade GAP Mix (ramp, seção 3) | B33: =B27 | C33: =C27 | D33: =D27 | E33: =E27 | F33: =F27
A34: Varejo Total (orgânico + GAP mix) | B34: =B32+B33 | C34: =C32+C33 | D34: =D32+D33 | E34: =E32+E33 | F34: =F32+F33
A35: Uplift % vs. Varejo orgânico | B35: =B33/B32 | C35: =C33/C32 | D35: =D33/D32 | E35: =E33/E32 | F35: =F33/F32
A37: Leitura
A38: • Este cálculo trata a oportunidade de GAP como incremental E ADICIONAL ao crescimento orgânico já modelado — não substitui as premissas de Premissas!B4 (25,5% a.a.), que já embutem alguma expansão de mix implícita. Antes de somar as duas linhas na Projeção Receita oficial, vale checar se não há dupla contagem.
A39: • O giro incremental de 50% é uma premissa de arranque conservadora — SKU novo tipicamente gira abaixo da média madura da loja. Ajustável na célula A5.
A40: • O ramp de 3 anos (padrão) é uma primeira hipótese de execução — pode ser encurtado se o time comercial priorizar ativação rápida das lojas 'Sem mix' (ver análise em slides, seção de recomendações).
A41: • Fat. médio por SKU está sujeito à limitação de escopo descrita acima (nota de seção 1) — mais confiável em termos relativos (comparação entre estados) do que em valor absoluto.

Sheet B2B por Estado e Cidade
A1: B2B — FATURAMENTO POR ESTADO E CIDADE (2025-2030)
A2: Base real: transações B2B 2025 por cidade (Simulador Orfeu.xlsx, aba Base_Unitaria). Cada cidade cresce na MESMA taxa do seu estado em 'Projeção Receita' (mix de cidade dentro do estado mantido constante de 2025 — premissa a validar com dado real de 2026+ quando disponível). Cidades com faturamento 2025 abaixo de R$30k ficam agrupadas em 'Outras cidades do estado'.
A4: UF | B4: Cidade | C4: 2025 | D4: 2026 | E4: 2027 | F4: 2028 | G4: 2029 | H4: 2030 | I4: Mult. 2030/2025
A5: SP | B5: TOTAL SP (B2B) | C5: ='Projeção Receita'!D5 | D5: ='Projeção Receita'!E5 | E5: ='Projeção Receita'!F5 | F5: ='Projeção Receita'!G5 | G5: ='Projeção Receita'!H5 | H5: ='Projeção Receita'!I5 | I5: =I5/C5
A6: SP | B6: Sao Paulo | C6: 7342395 | D6: =$C6*('Projeção Receita'!E5/'Projeção Receita'!$D$5) | E6: =$C6*('Projeção Receita'!F5/'Projeção Receita'!$D$5) | F6: =$C6*('Projeção Receita'!G5/'Projeção Receita'!$D$5) | G6: =$C6*('Projeção Receita'!H5/'Projeção Receita'!$D$5) | H6: =$C6*('Projeção Receita'!I5/'Projeção Receita'!$D$5) | I6: =I6/C6
A7: SP | B7: Jundiai | C7: 955415.82 | D7: =$C7*('Projeção Receita'!E5/'Projeção Receita'!$D$5) | E7: =$C7*('Projeção Receita'!F5/'Projeção Receita'!$D$5) | F7: =$C7*('Projeção Receita'!G5/'Projeção Receita'!$D$5) | G7: =$C7*('Projeção Receita'!H5/'Projeção Receita'!$D$5) | H7: =$C7*('Projeção Receita'!I5/'Projeção Receita'!$D$5) | I7: =I7/C7
A8: SP | B8: Catanduva | C8: 521371.76 | D8: =$C8*('Projeção Receita'!E5/'Projeção Receita'!$D$5) | E8: =$C8*('Projeção Receita'!F5/'Projeção Receita'!$D$5) | F8: =$C8*('Projeção Receita'!G5/'Projeção Receita'!$D$5) | G8: =$C8*('Projeção Receita'!H5/'Projeção Receita'!$D$5) | H8: =$C8*('Projeção Receita'!I5/'Projeção Receita'!$D$5) | I8: =I8/C8
A9: SP | B9: Barueri | C9: 512216.01 | D9: =$C9*('Projeção Receita'!E5/'Projeção Receita'!$D$5) | E9: =$C9*('Projeção Receita'!F5/'Projeção Receita'!$D$5) | F9: =$C9*('Projeção Receita'!G5/'Projeção Receita'!$D$5) | G9: =$C9*('Projeção Receita'!H5/'Projeção Receita'!$D$5) | H9: =$C9*('Projeção Receita'!I5/'Projeção Receita'!$D$5) | I9: =I9/C9
A10: SP | B10: Santa Barbara D Oeste | C10: 389755.44 | D10: =$C10*('Projeção Receita'!E5/'Projeção Receita'!$D$5) | E10: =$C10*('Projeção Receita'!F5/'Projeção Receita'!$D$5) | F10: =$C10*('Projeção Receita'!G5/'Projeção Receita'!$D$5) | G10: =$C10*('Projeção Receita'!H5/'Projeção Receita'!$D$5) | H10: =$C10*('Projeção Receita'!I5/'Projeção Receita'!$D$5) | I10: =I10/C10
A11: SP | B11: Sao Carlos | C11: 328493.52 | D11: =$C11*('Projeção Receita'!E5/'Projeção Receita'!$D$5) | E11: =$C11*('Projeção Receita'!F5/'Projeção Receita'!$D$5) | F11: =$C11*('Projeção Receita'!G5/'Projeção Receita'!$D$5) | G11: =$C11*('Projeção Receita'!H5/'Projeção Receita'!$D$5) | H11: =$C11*('Projeção Receita'!I5/'Projeção Receita'!$D$5) | I11: =I11/C11
A12: SP | B12: Guararema | C12: 320997.92 | D12: =$C12*('Projeção Receita'!E5/'Projeção Receita'!$D$5) | E12: =$C12*('Projeção Receita'!F5/'Projeção Receita'!$D$5) | F12: =$C12*('Projeção Receita'!G5/'Projeção Receita'!$D$5) | G12: =$C12*('Projeção Receita'!H5/'Projeção Receita'!$D$5) | H12: =$C12*('Projeção Receita'!I5/'Projeção Receita'!$D$5) | I12: =I12/C12
A13: SP | B13: Campinas | C13: 303816.18 | D13: =$C13*('Projeção Receita'!E5/'Projeção Receita'!$D$5) | E13: =$C13*('Projeção Receita'!F5/'Projeção Receita'!$D$5) | F13: =$C13*('Projeção Receita'!G5/'Projeção Receita'!$D$5) | G13: =$C13*('Projeção Receita'!H5/'Projeção Receita'!$D$5) | H13: =$C13*('Projeção Receita'!I5/'Projeção Receita'!$D$5) | I13: =I13/C13
A14: SP | B14: Santa Cruz Do Rio Pardo | C14: 299135.64 | D14: =$C14*('Projeção Receita'!E5/'Projeção Receita'!$D$5) | E14: =$C14*('Projeção Receita'!F5/'Projeção Receita'!$D$5) | F14: =$C14*('Projeção Receita'!G5/'Projeção Receita'!$D$5) | G14: =$C14*('Projeção Receita'!H5/'Projeção Receita'!$D$5) | H14: =$C14*('Projeção Receita'!I5/'Projeção Receita'!$D$5) | I14: =I14/C14
A15: SP | B15: Limeira | C15: 281583 | D15: =$C15*('Projeção Receita'!E5/'Projeção Receita'!$D$5) | E15: =$C15*('Projeção Receita'!F5/'Projeção Receita'!$D$5) | F15: =$C15*('Projeção Receita'!G5/'Projeção Receita'!$D$5) | G15: =$C15*('Projeção Receita'!H5/'Projeção Receita'!$D$5) | H15: =$C15*('Projeção Receita'!I5/'Projeção Receita'!$D$5) | I15: =I15/C15
A16: SP | B16: Queluz | C16: 269053.01 | D16: =$C16*('Projeção Receita'!E5/'Projeção Receita'!$D$5) | E16: =$C16*('Projeção Receita'!F5/'Projeção Receita'!$D$5) | F16: =$C16*('Projeção Receita'!G5/'Projeção Receita'!$D$5) | G16: =$C16*('Projeção Receita'!H5/'Projeção Receita'!$D$5) | H16: =$C16*('Projeção Receita'!I5/'Projeção Receita'!$D$5) | I16: =I16/C16
A17: SP | B17: Guaratingueta | C17: 233422.16 | D17: =$C17*('Projeção Receita'!E5/'Projeção Receita'!$D$5) | E17: =$C17*('Projeção Receita'!F5/'Projeção Receita'!$D$5) | F17: =$C17*('Projeção Receita'!G5/'Projeção Receita'!$D$5) | G17: =$C17*('Projeção Receita'!H5/'Projeção Receita'!$D$5) | H17: =$C17*('Projeção Receita'!I5/'Projeção Receita'!$D$5) | I17: =I17/C17
A18: SP | B18: Mairipora | C18: 188796.31 | D18: =$C18*('Projeção Receita'!E5/'Projeção Receita'!$D$5) | E18: =$C18*('Projeção Receita'!F5/'Projeção Receita'!$D$5) | F18: =$C18*('Projeção Receita'!G5/'Projeção Receita'!$D$5) | G18: =$C18*('Projeção Receita'!H5/'Projeção Receita'!$D$5) | H18: =$C18*('Projeção Receita'!I5/'Projeção Receita'!$D$5) | I18: =I18/C18
A19: SP | B19: Registro | C19: 183827.05 | D19: =$C19*('Projeção Receita'!E5/'Projeção Receita'!$D$5) | E19: =$C19*('Projeção Receita'!F5/'Projeção Receita'!$D$5) | F19: =$C19*('Projeção Receita'!G5/'Projeção Receita'!$D$5) | G19: =$C19*('Projeção Receita'!H5/'Projeção Receita'!$D$5) | H19: =$C19*('Projeção Receita'!I5/'Projeção Receita'!$D$5) | I19: =I19/C19
A20: SP | B20: Pindamonhangaba | C20: 176328.01 | D20: =$C20*('Projeção Receita'!E5/'Projeção Receita'!$D$5) | E20: =$C20*('Projeção Receita'!F5/'Projeção Receita'!$D$5) | F20: =$C20*('Projeção Receita'!G5/'Projeção Receita'!$D$5) | G20: =$C20*('Projeção Receita'!H5/'Projeção Receita'!$D$5) | H20: =$C20*('Projeção Receita'!I5/'Projeção Receita'!$D$5) | I20: =I20/C20
A21: SP | B21: Pariquera-Acu | C21: 176318.36 | D21: =$C21*('Projeção Receita'!E5/'Projeção Receita'!$D$5) | E21: =$C21*('Projeção Receita'!F5/'Projeção Receita'!$D$5) | F21: =$C21*('Projeção Receita'!G5/'Projeção Receita'!$D$5) | G21: =$C21*('Projeção Receita'!H5/'Projeção Receita'!$D$5) | H21: =$C21*('Projeção Receita'!I5/'Projeção Receita'!$D$5) | I21: =I21/C21
A22: SP | B22: Jandira | C22: 166213.13 | D22: =$C22*('Projeção Receita'!E5/'Projeção Receita'!$D$5) | E22: =$C22*('Projeção Receita'!F5/'Projeção Receita'!$D$5) | F22: =$C22*('Projeção Receita'!G5/'Projeção Receita'!$D$5) | G22: =$C22*('Projeção Receita'!H5/'Projeção Receita'!$D$5) | H22: =$C22*('Projeção Receita'!I5/'Projeção Receita'!$D$5) | I22: =I22/C22
A23: SP | B23: Ribeirao Preto | C23: 158227.72 | D23: =$C23*('Projeção Receita'!E5/'Projeção Receita'!$D$5) | E23: =$C23*('Projeção Receita'!F5/'Projeção Receita'!$D$5) | F23: =$C23*('Projeção Receita'!G5/'Projeção Receita'!$D$5) | G23: =$C23*('Projeção Receita'!H5/'Projeção Receita'!$D$5) | H23: =$C23*('Projeção Receita'!I5/'Projeção Receita'!$D$5) | I23: =I23/C23
A24: SP | B24: Pirassununga | C24: 154951.38 | D24: =$C24*('Projeção Receita'!E5/'Projeção Receita'!$D$5) | E24: =$C24*('Projeção Receita'!F5/'Projeção Receita'!$D$5) | F24: =$C24*('Projeção Receita'!G5/'Projeção Receita'!$D$5) | G24: =$C24*('Projeção Receita'!H5/'Projeção Receita'!$D$5) | H24: =$C24*('Projeção Receita'!I5/'Projeção Receita'!$D$5) | I24: =I24/C24
A25: SP | B25: Cordeiropolis | C25: 152347.68 | D25: =$C25*('Projeção Receita'!E5/'Projeção Receita'!$D$5) | E25: =$C25*('Projeção Receita'!F5/'Projeção Receita'!$D$5) | F25: =$C25*('Projeção Receita'!G5/'Projeção Receita'!$D$5) | G25: =$C25*('Projeção Receita'!H5/'Projeção Receita'!$D$5) | H25: =$C25*('Projeção Receita'!I5/'Projeção Receita'!$D$5) | I25: =I25/C25
A26: SP | B26: Pardinho | C26: 146586.38 | D26: =$C26*('Projeção Receita'!E5/'Projeção Receita'!$D$5) | E26: =$C26*('Projeção Receita'!F5/'Projeção Receita'!$D$5) | F26: =$C26*('Projeção Receita'!G5/'Projeção Receita'!$D$5) | G26: =$C26*('Projeção Receita'!H5/'Projeção Receita'!$D$5) | H26: =$C26*('Projeção Receita'!I5/'Projeção Receita'!$D$5) | I26: =I26/C26
A27: SP | B27: Guarulhos | C27: 140336.53 | D27: =$C27*('Projeção Receita'!E5/'Projeção Receita'!$D$5) | E27: =$C27*('Projeção Receita'!F5/'Projeção Receita'!$D$5) | F27: =$C27*('Projeção Receita'!G5/'Projeção Receita'!$D$5) | G27: =$C27*('Projeção Receita'!H5/'Projeção Receita'!$D$5) | H27: =$C27*('Projeção Receita'!I5/'Projeção Receita'!$D$5) | I27: =I27/C27
A28: SP | B28: Miracatu | C28: 131830.06 | D28: =$C28*('Projeção Receita'!E5/'Projeção Receita'!$D$5) | E28: =$C28*('Projeção Receita'!F5/'Projeção Receita'!$D$5) | F28: =$C28*('Projeção Receita'!G5/'Projeção Receita'!$D$5) | G28: =$C28*('Projeção Receita'!H5/'Projeção Receita'!$D$5) | H28: =$C28*('Projeção Receita'!I5/'Projeção Receita'!$D$5) | I28: =I28/C28
A29: SP | B29: Jarinu | C29: 130292.6 | D29: =$C29*('Projeção Receita'!E5/'Projeção Receita'!$D$5) | E29: =$C29*('Projeção Receita'!F5/'Projeção Receita'!$D$5) | F29: =$C29*('Projeção Receita'!G5/'Projeção Receita'!$D$5) | G29: =$C29*('Projeção Receita'!H5/'Projeção Receita'!$D$5) | H29: =$C29*('Projeção Receita'!I5/'Projeção Receita'!$D$5) | I29: =I29/C29
A30: SP | B30: Aracariguama | C30: 113363.56 | D30: =$C30*('Projeção Receita'!E5/'Projeção Receita'!$D$5) | E30: =$C30*('Projeção Receita'!F5/'Projeção Receita'!$D$5) | F30: =$C30*('Projeção Receita'!G5/'Projeção Receita'!$D$5) | G30: =$C30*('Projeção Receita'!H5/'Projeção Receita'!$D$5) | H30: =$C30*('Projeção Receita'!I5/'Projeção Receita'!$D$5) | I30: =I30/C30
A31: SP | B31: Bauru | C31: 96658.13 | D31: =$C31*('Projeção Receita'!E5/'Projeção Receita'!$D$5) | E31: =$C31*('Projeção Receita'!F5/'Projeção Receita'!$D$5) | F31: =$C31*('Projeção Receita'!G5/'Projeção Receita'!$D$5) | G31: =$C31*('Projeção Receita'!H5/'Projeção Receita'!$D$5) | H31: =$C31*('Projeção Receita'!I5/'Projeção Receita'!$D$5) | I31: =I31/C31
A32: SP | B32: Itatiba | C32: 87081.6 | D32: =$C32*('Projeção Receita'!E5/'Projeção Receita'!$D$5) | E32: =$C32*('Projeção Receita'!F5/'Projeção Receita'!$D$5) | F32: =$C32*('Projeção Receita'!G5/'Projeção Receita'!$D$5) | G32: =$C32*('Projeção Receita'!H5/'Projeção Receita'!$D$5) | H32: =$C32*('Projeção Receita'!I5/'Projeção Receita'!$D$5) | I32: =I32/C32
A33: SP | B33: Itupeva | C33: 86643.7 | D33: =$C33*('Projeção Receita'!E5/'Projeção Receita'!$D$5) | E33: =$C33*('Projeção Receita'!F5/'Projeção Receita'!$D$5) | F33: =$C33*('Projeção Receita'!G5/'Projeção Receita'!$D$5) | G33: =$C33*('Projeção Receita'!H5/'Projeção Receita'!$D$5) | H33: =$C33*('Projeção Receita'!I5/'Projeção Receita'!$D$5) | I33: =I33/C33
A34: SP | B34: Santo Andre | C34: 83026.06 | D34: =$C34*('Projeção Receita'!E5/'Projeção Receita'!$D$5) | E34: =$C34*('Projeção Receita'!F5/'Projeção Receita'!$D$5) | F34: =$C34*('Projeção Receita'!G5/'Projeção Receita'!$D$5) | G34: =$C34*('Projeção Receita'!H5/'Projeção Receita'!$D$5) | H34: =$C34*('Projeção Receita'!I5/'Projeção Receita'!$D$5) | I34: =I34/C34
A35: SP | B35: Iaras | C35: 64796.89 | D35: =$C35*('Projeção Receita'!E5/'Projeção Receita'!$D$5) | E35: =$C35*('Projeção Receita'!F5/'Projeção Receita'!$D$5) | F35: =$C35*('Projeção Receita'!G5/'Projeção Receita'!$D$5) | G35: =$C35*('Projeção Receita'!H5/'Projeção Receita'!$D$5) | H35: =$C35*('Projeção Receita'!I5/'Projeção Receita'!$D$5) | I35: =I35/C35
A36: SP | B36: Guaruja | C36: 55019.8 | D36: =$C36*('Projeção Receita'!E5/'Projeção Receita'!$D$5) | E36: =$C36*('Projeção Receita'!F5/'Projeção Receita'!$D$5) | F36: =$C36*('Projeção Receita'!G5/'Projeção Receita'!$D$5) | G36: =$C36*('Projeção Receita'!H5/'Projeção Receita'!$D$5) | H36: =$C36*('Projeção Receita'!I5/'Projeção Receita'!$D$5) | I36: =I36/C36
A37: SP | B37: Osasco | C37: 54495.86 | D37: =$C37*('Projeção Receita'!E5/'Projeção Receita'!$D$5) | E37: =$C37*('Projeção Receita'!F5/'Projeção Receita'!$D$5) | F37: =$C37*('Projeção Receita'!G5/'Projeção Receita'!$D$5) | G37: =$C37*('Projeção Receita'!H5/'Projeção Receita'!$D$5) | H37: =$C37*('Projeção Receita'!I5/'Projeção Receita'!$D$5) | I37: =I37/C37
A38: SP | B38: Ilhabela | C38: 46931.9 | D38: =$C38*('Projeção Receita'!E5/'Projeção Receita'!$D$5) | E38: =$C38*('Projeção Receita'!F5/'Projeção Receita'!$D$5) | F38: =$C38*('Projeção Receita'!G5/'Projeção Receita'!$D$5) | G38: =$C38*('Projeção Receita'!H5/'Projeção Receita'!$D$5) | H38: =$C38*('Projeção Receita'!I5/'Projeção Receita'!$D$5) | I38: =I38/C38
A39: SP | B39: Cotia | C39: 45658.32 | D39: =$C39*('Projeção Receita'!E5/'Projeção Receita'!$D$5) | E39: =$C39*('Projeção Receita'!F5/'Projeção Receita'!$D$5) | F39: =$C39*('Projeção Receita'!G5/'Projeção Receita'!$D$5) | G39: =$C39*('Projeção Receita'!H5/'Projeção Receita'!$D$5) | H39: =$C39*('Projeção Receita'!I5/'Projeção Receita'!$D$5) | I39: =I39/C39
A40: SP | B40: Ourinhos | C40: 44680.2 | D40: =$C40*('Projeção Receita'!E5/'Projeção Receita'!$D$5) | E40: =$C40*('Projeção Receita'!F5/'Projeção Receita'!$D$5) | F40: =$C40*('Projeção Receita'!G5/'Projeção Receita'!$D$5) | G40: =$C40*('Projeção Receita'!H5/'Projeção Receita'!$D$5) | H40: =$C40*('Projeção Receita'!I5/'Projeção Receita'!$D$5) | I40: =I40/C40
A41: SP | B41: Braganca Paulista | C41: 40841.12 | D41: =$C41*('Projeção Receita'!E5/'Projeção Receita'!$D$5) | E41: =$C41*('Projeção Receita'!F5/'Projeção Receita'!$D$5) | F41: =$C41*('Projeção Receita'!G5/'Projeção Receita'!$D$5) | G41: =$C41*('Projeção Receita'!H5/'Projeção Receita'!$D$5) | H41: =$C41*('Projeção Receita'!I5/'Projeção Receita'!$D$5) | I41: =I41/C41
...

Sheet Funcionários
A1: PROJEÇÃO DE FUNCIONÁRIOS — POR ESTADO E FUNÇÃO
A2: Regra: Varejo Direto (payroll Orfeu) apenas em SP/RJ — inclui Vendedor e Promotor/Abordador próprios. Demais estados = Representante terceiro (comissionado) e Promotores/Abordadores via agência externa — ambos fora da folha. Cidades-foco B2B → Comercial primeiro, depois Barista.
A3: Nota: baseline 2025 de Vendedor Varejo Direto (SP=3, RJ=1) corrigido para bater com o headcount real no Organograma_Time_Comercial_SNomes.xlsx, aba Avaliação (Funcionários 4, 5, 6 em SP; Funcionário 8 no RJ).
A4: UF | B4: Estado | C4: Função | D4: 2025 (atual) | E4: 2026 | F4: 2027 | G4: 2028 | H4: 2029 | I4: 2030
A5: SP | B5: São Paulo | C5: Vendedor Varejo Direto (SP/RJ) | D5: 3 | E5: =$D$5+ROUNDDOWN(MAX(0,'Projeção Receita'!E4-'Projeção Receita'!$D$4)/Premissas!$B$14,0) | F5: =$D$5+ROUNDDOWN(MAX(0,'Projeção Receita'!F4-'Projeção Receita'!$D$4)/Premissas!$B$14,0) | G5: =$D$5+ROUNDDOWN(MAX(0,'Projeção Receita'!G4-'Projeção Receita'!$D$4)/Premissas!$B$14,0) | H5: =$D$5+ROUNDDOWN(MAX(0,'Projeção Receita'!H4-'Projeção Receita'!$D$4)/Premissas!$B$14,0) | I5: =$D$5+ROUNDDOWN(MAX(0,'Projeção Receita'!I4-'Projeção Receita'!$D$4)/Premissas!$B$14,0)
A6: SP | B6: São Paulo | C6: Promotor/Abordador Próprio (SP/RJ) | D6: 0 | E6: =ROUNDDOWN(MAX(0,('Projeção Receita'!E4-'Projeção Receita'!$D$4))/1000000*Premissas!$B$15,0) | F6: =ROUNDDOWN(MAX(0,('Projeção Receita'!F4-'Projeção Receita'!$D$4))/1000000*Premissas!$B$15,0) | G6: =ROUNDDOWN(MAX(0,('Projeção Receita'!G4-'Projeção Receita'!$D$4))/1000000*Premissas!$B$15,0) | H6: =ROUNDDOWN(MAX(0,('Projeção Receita'!H4-'Projeção Receita'!$D$4))/1000000*Premissas!$B$15,0) | I6: =ROUNDDOWN(MAX(0,('Projeção Receita'!I4-'Projeção Receita'!$D$4))/1000000*Premissas!$B$15,0)
